Workbook
Name OLE_LINK1: 'PASTE - Match 2'!$L$3

Sheet PASTE - Match 2
E1: =IF(C3="Employment_1","07/2021 to present",IF(C3="Employment_2","04/2020 to 06/2021",IF(C3="Employment_3","08/2018 to 03/2020",IF(C3="Employment_4","06/2017 to 07/2018",IF(C3="Employment_5","08/2016 to 06/2017",""))))) | L1: STEP ONE: Declare City | O1: Denver, CO | T1: Form 1 | U1: Form 2 | W1: New | X1: Old
A2: ID | B2: Static | C2: Emp (LU) | D2: Emp (Descriptions) | E2: Years | F2: Education | G2: Certifications | H2: Skills | I2: References | L2: STEP TWO: Paste from Word Document into I3 below | P2: =Q2/12 -> 1.8333333 | Q2: 22 | R2: 1 | S2: 2 | T2: 2021-2023 | U2: 2021-2023 | V2: 2 | W2: =R2 -> 1 | X2: 1 | Y2: 20 | Z2: =Y2/12 -> 1.6666667
A3: =B3&C3&F3&G3&H3&I3 -> Name | B3: Name | C3: ="" | E3: =IF(C3="Employment_1","September 2021 - Present",IF(C3="Employment_2","July 2020 - August 2021",IF(C3="Employment_3","April 2019 - June 2020",IF(C3="Employment_4","August 2017 - March 2019",IF(C3="Employment_5","October 2016 - July 2017",""))))) | I3: =IF(L3="References available on request.","References","") | L3: Male Name 2 | P3: =Q3/12 -> 1.1666667 | Q3: 14 | R3: 2 | S3: 1 | T3: 2020-2021 | U3: 2020-2021 | V3: 1 | W3: =R5 -> 4 | X3: 3 | Y3: =Q5 -> 13 | Z3: =Y3/12 -> 1.0833333
A4: =B4&C4&F4&G4&H4&I4 -> Location | B4: Location | C4: ="" | E4: =IF(C4="Employment_1","September 2021 - Present",IF(C4="Employment_2","July 2020 - August 2021",IF(C4="Employment_3","April 2019 - June 2020",IF(C4="Employment_4","August 2017 - March 2019",IF(C4="Employment_5","October 2016 - July 2017",""))))) | G4: =IF(L3="Certifications","Certification","") | I4: =IF(L4="References available on request.","References","") | L4: City, State | P4: =Q4/12 -> 1.5833333 | Q4: 19 | R4: 3 | S4: 2 | T4: 2018-2020 | U4: 2019-2020 | V4: 1 | W4: =R3 -> 2 | X4: 4 | Y4: =Q3 -> 14 | Z4: =Y4/12 -> 1.1666667
A5: =B5&C5&F5&G5&H5&I5 -> Phone | B5: Phone | C5: ="" | E5: =IF(C5="Employment_1","September 2021 - Present",IF(C5="Employment_2","July 2020 - August 2021",IF(C5="Employment_3","April 2019 - June 2020",IF(C5="Employment_4","August 2017 - March 2019",IF(C5="Employment_5","October 2016 - July 2017",""))))) | F5: =IF(OR(AND(L2="Education",L5="2013-2017"),ISNUMBER(FIND("GED",M5))),"High School",IF(AND(L3="Education",L4="No Post-Secondary"),"Post Secondary",IF(AND(L3="Education",L4="Bachelor's Degree"),"Post Secondary",IF(AND(L3="Education",L4="Associate's Degree"),"Post Secondary","")))) | G5: =IF(L4="Certifications","Certification","") | I5: =IF(L5="References available on request.","References","") | L5: Phone Number 2 | P5: =Q5/12 -> 1.0833333 | Q5: 13 | R5: 4 | S5: 1 | T5: 2017-2018 | U5: 2017-2019 | V5: 2 | W5: =R4 -> 3 | X5: 2 | Y5: =Q4 -> 19 | Z5: =Y5/12 -> 1.5833333
A6: =B6&C6&F6&G6&H6&I6 -> Email | B6: Email | C6: ="" | E6: =IF(C6="Employment_1","September 2021 - Present",IF(C6="Employment_2","July 2020 - August 2021",IF(C6="Employment_3","April 2019 - June 2020",IF(C6="Employment_4","August 2017 - March 2019",IF(C6="Employment_5","October 2016 - July 2017",""))))) | F6: =IF(OR(AND(L3="Education",L6="2013-2017"),ISNUMBER(FIND("GED",M6))),"High School",IF(AND(L4="Education",L5="No Post-Secondary"),"Post Secondary",IF(AND(L4="Education",L5="Bachelor's Degree"),"Post Secondary",IF(AND(L4="Education",L5="Associate's Degree"),"Post Secondary","")))) | G6: =IF(L5="Certifications","Certification","") | I6: =IF(L6="References available on request.","References","") | L6: email | Q6: 10 | Y6: 10
A7: =B7&C7&F7&G7&H7&I7 -> Pronouns | B7: Pronouns | C7: ="" | E7: =IF(C7="Employment_1","September 2021 - Present",IF(C7="Employment_2","July 2020 - August 2021",IF(C7="Employment_3","April 2019 - June 2020",IF(C7="Employment_4","August 2017 - March 2019",IF(C7="Employment_5","October 2016 - July 2017",""))))) | F7: =IF(OR(AND(L4="Education",L7="2013-2017"),ISNUMBER(FIND("GED",M7))),"High School",IF(AND(L5="Education",L6="No Post-Secondary"),"Post Secondary",IF(AND(L5="Education",L6="Bachelor's Degree"),"Post Secondary",IF(AND(L5="Education",L6="Associate's Degree"),"Post Secondary","")))) | G7: =IF(L6="Certifications","Certification","") | I7: =IF(L7="References available on request.","References","") | L7: no pronouns | S7: =22/14 -> 1.5714286 | T7: =S7*80000 -> 125714.29
A8: =B8&C8&F8&G8&H8&I8 | B8: ="" | C8: ="" | E8: =IF(C8="Employment_1","September 2021 - Present",IF(C8="Employment_2","July 2020 - August 2021",IF(C8="Employment_3","April 2019 - June 2020",IF(C8="Employment_4","August 2017 - March 2019",IF(C8="Employment_5","October 2016 - July 2017",""))))) | F8: =IF(OR(AND(L5="Education",L8="2013-2017"),ISNUMBER(FIND("GED",M8))),"High School",IF(AND(L6="Education",L7="No Post-Secondary"),"Post Secondary",IF(AND(L6="Education",L7="Bachelor's Degree"),"Post Secondary",IF(AND(L6="Education",L7="Associate's Degree"),"Post Secondary","")))) | G8: =IF(L7="Certifications","Certification","") | H8: =IF(L7="Skills","Skill_1",IF(L6="Skills","Skill_2",IF(L5="Skills","Skill_3",IF(L4="Skills","Skill_4",IF(L3="Skills","Skill_5",IF(L2="Skills","Skill_6","")))))) | I8: =IF(L8="References available on request.","References","")
A9: =B9&C9&F9&G9&H9&I9 | B9: ="" | C9: ="" | E9: =IF(C9="Employment_1","September 2021 - Present",IF(C9="Employment_2","July 2020 - August 2021",IF(C9="Employment_3","April 2019 - June 2020",IF(C9="Employment_4","August 2017 - March 2019",IF(C9="Employment_5","October 2016 - July 2017",""))))) | F9: =IF(OR(AND(L6="Education",L9="2013-2017"),ISNUMBER(FIND("GED",M9))),"High School",IF(AND(L7="Education",L8="No Post-Secondary"),"Post Secondary",IF(AND(L7="Education",L8="Bachelor's Degree"),"Post Secondary",IF(AND(L7="Education",L8="Associate's Degree"),"Post Secondary","")))) | G9: =IF(L8="Certifications","Certification","") | H9: =IF(L8="Skills","Skill_1",IF(L7="Skills","Skill_2",IF(L6="Skills","Skill_3",IF(L5="Skills","Skill_4",IF(L4="Skills","Skill_5",IF(L3="Skills","Skill_6","")))))) | I9: =IF(L9="References available on request.","References","") | L9: Summary
A10: =B10&C10&F10&G10&H10&I10 -> Summary | B10: Summary | C10: ="" | E10: =IF(C10="Employment_1","September 2021 - Present",IF(C10="Employment_2","July 2020 - August 2021",IF(C10="Employment_3","April 2019 - June 2020",IF(C10="Employment_4","August 2017 - March 2019",IF(C10="Employment_5","October 2016 - July 2017",""))))) | F10: =IF(OR(AND(L7="Education",L10="2013-2017"),ISNUMBER(FIND("GED",M10))),"High School",IF(AND(L8="Education",L9="No Post-Secondary"),"Post Secondary",IF(AND(L8="Education",L9="Bachelor's Degree"),"Post Secondary",IF(AND(L8="Education",L9="Associate's Degree"),"Post Secondary","")))) | G10: =IF(L9="Certifications","Certification","") | H10: =IF(L9="Skills","Skill_1",IF(L8="Skills","Skill_2",IF(L7="Skills","Skill_3",IF(L6="Skills","Skill_4",IF(L5="Skills","Skill_5",IF(L4="Skills","Skill_6","")))))) | I10: =IF(L10="References available on request.","References","")
A11: =B11&C11&F11&G11&H11&I11 | B11: ="" | C11: ="" | E11: =IF(C11="Employment_1","September 2021 - Present",IF(C11="Employment_2","July 2020 - August 2021",IF(C11="Employment_3","April 2019 - June 2020",IF(C11="Employment_4","August 2017 - March 2019",IF(C11="Employment_5","October 2016 - July 2017",""))))) | F11: =IF(OR(AND(L8="Education",L11="2013-2017"),ISNUMBER(FIND("GED",M11))),"High School",IF(AND(L9="Education",L10="No Post-Secondary"),"Post Secondary",IF(AND(L9="Education",L10="Bachelor's Degree"),"Post Secondary",IF(AND(L9="Education",L10="Associate's Degree"),"Post Secondary","")))) | G11: =IF(L10="Certifications","Certification","") | H11: =IF(L10="Skills","Skill_1",IF(L9="Skills","Skill_2",IF(L8="Skills","Skill_3",IF(L7="Skills","Skill_4",IF(L6="Skills","Skill_5",IF(L5="Skills","Skill_6","")))))) | I11: =IF(L11="References available on request.","References","")
A12: =B12&C12&F12&G12&H12&I12 | B12: ="" | C12: ="" | E12: =IF(C12="Employment_1","September 2021 - Present",IF(C12="Employment_2","July 2020 - August 2021",IF(C12="Employment_3","April 2019 - June 2020",IF(C12="Employment_4","August 2017 - March 2019",IF(C12="Employment_5","October 2016 - July 2017",""))))) | F12: =IF(OR(AND(L9="Education",L12="2013-2017"),ISNUMBER(FIND("GED",M12))),"High School",IF(AND(L10="Education",L11="No Post-Secondary"),"Post Secondary",IF(AND(L10="Education",L11="Bachelor's Degree"),"Post Secondary",IF(AND(L10="Education",L11="Associate's Degree"),"Post Secondary","")))) | G12: =IF(L11="Certifications","Certification","") | H12: =IF(L11="Skills","Skill_1",IF(L10="Skills","Skill_2",IF(L9="Skills","Skill_3",IF(L8="Skills","Skill_4",IF(L7="Skills","Skill_5",IF(L6="Skills","Skill_6","")))))) | I12: =IF(L12="References available on request.","References","") | L12: Education
A13: =B13&C13&F13&G13&H13&I13 | B13: ="" | E13: =IF(C13="Employment_1","September 2021 - Present",IF(C13="Employment_2","July 2020 - August 2021",IF(C13="Employment_3","April 2019 - June 2020",IF(C13="Employment_4","August 2017 - March 2019",IF(C13="Employment_5","October 2016 - July 2017",""))))) | F13: =IF(OR(AND(L10="Education",L13="2013-2017"),ISNUMBER(FIND("GED",M13))),"High School",IF(AND(L11="Education",L12="No Post-Secondary"),"Post Secondary",IF(AND(L11="Education",L12="Bachelor's Degree"),"Post Secondary",IF(AND(L11="Education",L12="Associate's Degree"),"Post Secondary","")))) | G13: =IF(L12="Certifications","Certification","") | H13: =IF(L12="Skills","Skill_1",IF(L11="Skills","Skill_2",IF(L10="Skills","Skill_3",IF(L9="Skills","Skill_4",IF(L8="Skills","Skill_5",IF(L7="Skills","Skill_6","")))))) | I13: =IF(L13="References available on request.","References","") | L13: Bachelor's Degree
A14: =B14&C14&F14&G14&H14&I14 -> Post Secondary | B14: ="" | E14: =IF(C14="Employment_1","September 2021 - Present",IF(C14="Employment_2","July 2020 - August 2021",IF(C14="Employment_3","April 2019 - June 2020",IF(C14="Employment_4","August 2017 - March 2019",IF(C14="Employment_5","October 2016 - July 2017",""))))) | F14: =IF(OR(AND(L11="Education",L14="2013-2017"),ISNUMBER(FIND("GED",M14))),"High School",IF(AND(L12="Education",L13="No Post-Secondary"),"Post Secondary",IF(AND(L12="Education",L13="Bachelor's Degree"),"Post Secondary",IF(AND(L12="Education",L13="Associate's Degree"),"Post Secondary","")))) -> Post Secondary | G14: =IF(L13="Certifications","Certification","") | H14: =IF(L13="Skills","Skill_1",IF(L12="Skills","Skill_2",IF(L11="Skills","Skill_3",IF(L10="Skills","Skill_4",IF(L9="Skills","Skill_5",IF(L8="Skills","Skill_6","")))))) | I14: =IF(L14="References available on request.","References","") | L14: 2018-2022 | M14: Psychology | N14: University A
A15: =B15&C15&F15&G15&H15&I15 -> High School | B15: ="" | E15: =IF(C15="Employment_1","September 2021 - Present",IF(C15="Employment_2","July 2020 - August 2021",IF(C15="Employment_3","April 2019 - June 2020",IF(C15="Employment_4","August 2017 - March 2019",IF(C15="Employment_5","October 2016 - July 2017",""))))) | F15: =IF(OR(AND(L12="Education",L15="2013-2017"),ISNUMBER(FIND("GED",M15))),"High School",IF(AND(L13="Education",L14="No Post-Secondary"),"Post Secondary",IF(AND(L13="Education",L14="Bachelor's Degree"),"Post Secondary",IF(AND(L13="Education",L14="Associate's Degree"),"Post Secondary","")))) -> High School | G15: =IF(L14="Certifications","Certification","") | H15: =IF(L14="Skills","Skill_1",IF(L13="Skills","Skill_2",IF(L12="Skills","Skill_3",IF(L11="Skills","Skill_4",IF(L10="Skills","Skill_5",IF(L9="Skills","Skill_6","")))))) | I15: =IF(L15="References available on request.","References","") | L15: 2013-2017 | M15: High School D
A16: =B16&C16&F16&G16&H16&I16 | B16: ="" | E16: =IF(C16="Employment_1","September 2021 - Present",IF(C16="Employment_2","July 2020 - August 2021",IF(C16="Employment_3","April 2019 - June 2020",IF(C16="Employment_4","August 2017 - March 2019",IF(C16="Employment_5","October 2016 - July 2017",""))))) | F16: =IF(OR(AND(L13="Education",L16="2013-2017"),ISNUMBER(FIND("GED",M16))),"High School",IF(AND(L14="Education",L15="No Post-Secondary"),"Post Secondary",IF(AND(L14="Education",L15="Bachelor's Degree"),"Post Secondary",IF(AND(L14="Education",L15="Associate's Degree"),"Post Secondary","")))) | G16: =IF(L15="Certifications","Certification","") | H16: =IF(L15="Skills","Skill_1",IF(L14="Skills","Skill_2",IF(L13="Skills","Skill_3",IF(L12="Skills","Skill_4",IF(L11="Skills","Skill_5",IF(L10="Skills","Skill_6","")))))) | I16: =IF(L16="References available on request.","References","")
A17: =B17&C17&F17&G17&H17&I17 | B17: ="" | E17: =IF(C17="Employment_1","September 2021 - Present",IF(C17="Employment_2","July 2020 - August 2021",IF(C17="Employment_3","April 2019 - June 2020",IF(C17="Employment_4","August 2017 - March 2019",IF(C17="Employment_5","October 2016 - July 2017",""))))) | F17: =IF(OR(AND(L14="Education",L17="2013-2017"),ISNUMBER(FIND("GED",M17))),"High School",IF(AND(L15="Education",L16="No Post-Secondary"),"Post Secondary",IF(AND(L15="Education",L16="Bachelor's Degree"),"Post Secondary",IF(AND(L15="Education",L16="Associate's Degree"),"Post Secondary","")))) | G17: =IF(L16="Certifications","Certification","") | H17: =IF(L16="Skills","Skill_1",IF(L15="Skills","Skill_2",IF(L14="Skills","Skill_3",IF(L13="Skills","Skill_4",IF(L12="Skills","Skill_5",IF(L11="Skills","Skill_6","")))))) | I17: =IF(L17="References available on request.","References","") | L17: Employment History
A18: =B18&C18&F18&G18&H18&I18 -> Employment_1 | B18: ="" | C18: =IF(L17="Employment History","Employment_1",NA()) -> Employment_1 | E18: =IF(C18="Employment_1","September 2021 - Present",IF(C18="Employment_2","July 2020 - August 2021",IF(C18="Employment_3","April 2019 - June 2020",IF(C18="Employment_4","August 2017 - March 2019",IF(C18="Employment_5","October 2016 - July 2017",""))))) -> September 2021 - Present | F18: =IF(OR(AND(L15="Education",L18="2013-2017"),ISNUMBER(FIND("GED",M18))),"High School",IF(AND(L16="Education",L17="No Post-Secondary"),"Post Secondary",IF(AND(L16="Education",L17="Bachelor's Degree"),"Post Secondary",IF(AND(L16="Education",L17="Associate's Degree"),"Post Secondary","")))) | G18: =IF(L17="Certifications","Certification","") | H18: =IF(L17="Skills","Skill_1",IF(L16="Skills","Skill_2",IF(L15="Skills","Skill_3",IF(L14="Skills","Skill_4",IF(L13="Skills","Skill_5",IF(L12="Skills","Skill_6","")))))) | I18: =IF(L18="References available on request.","References","") | L18: 2021-2023 | M18: Certified Nursing Assistant | N18: Company D
A19: =B19&C19&F19&G19&H19&I19 -> Employment_Description_11 | B19: ="" | C19: =IF(ISERROR($C$18),NA(),IF(AND(L19="",M19=""),"","Employment_Description_11")) -> Employment_Description_11 | D19: =IFERROR(INDEX('LU - Ad Hoc Baker Fix'!$D:$D,MATCH(M$18&$C19,'LU - Ad Hoc Baker Fix'!$A:$A,0)),$M19) -> Answered call lights and supported patient comfort and safety by adjusting bed rails and equipment | E19: =IF(C19="Employment_1","September 2021 - Present",IF(C19="Employment_2","July 2020 - August 2021",IF(C19="Employment_3","April 2019 - June 2020",IF(C19="Employment_4","August 2017 - March 2019",IF(C19="Employment_5","October 2016 - July 2017",""))))) | F19: =IF(OR(AND(L16="Education",L19="2013-2017"),ISNUMBER(FIND("GED",M19))),"High School",IF(AND(L17="Education",L18="No Post-Secondary"),"Post Secondary",IF(AND(L17="Education",L18="Bachelor's Degree"),"Post Secondary",IF(AND(L17="Education",L18="Associate's Degree"),"Post Secondary","")))) | G19: =IF(L18="Certifications","Certification","") | H19: =IF(L18="Skills","Skill_1",IF(L17="Skills","Skill_2",IF(L16="Skills","Skill_3",IF(L15="Skills","Skill_4",IF(L14="Skills","Skill_5",IF(L13="Skills","Skill_6","")))))) | I19: =IF(L19="References available on request.","References","") | M19: Answered call lights and supported patient comfort and safety by adjusting bed rails and equipment
A20: =B20&C20&F20&G20&H20&I20 -> Employment_Description_12 | B20: ="" | C20: =IF(ISERROR($C$18),NA(),IF(AND(L20="",M20=""),"","Employment_Description_12")) -> Employment_Description_12 | D20: =IFERROR(INDEX('LU - Ad Hoc Baker Fix'!$D:$D,MATCH(M$18&$C20,'LU - Ad Hoc Baker Fix'!$A:$A,0)),$M20) -> Promoted good oral and personal hygiene by aiding patients with shaving, bathing, and teeth brushing | E20: =IF(C20="Employment_1","September 2021 - Present",IF(C20="Employment_2","July 2020 - August 2021",IF(C20="Employment_3","April 2019 - June 2020",IF(C20="Employment_4","August 2017 - March 2019",IF(C20="Employment_5","October 2016 - July 2017",""))))) | F20: =IF(OR(AND(L17="Education",L20="2013-2017"),ISNUMBER(FIND("GED",M20))),"High School",IF(AND(L18="Education",L19="No Post-Secondary"),"Post Secondary",IF(AND(L18="Education",L19="Bachelor's Degree"),"Post Secondary",IF(AND(L18="Education",L19="Associate's Degree"),"Post Secondary","")))) | G20: =IF(L19="Certifications","Certification","") | H20: =IF(L19="Skills","Skill_1",IF(L18="Skills","Skill_2",IF(L17="Skills","Skill_3",IF(L16="Skills","Skill_4",IF(L15="Skills","Skill_5",IF(L14="Skills","Skill_6","")))))) | I20: =IF(L20="References available on request.","References","") | M20: Promoted good oral and personal hygiene by aiding patients with shaving, bathing, and teeth brushing
A21: =B21&C21&F21&G21&H21&I21 -> Employment_Description_13 | B21: ="" | C21: =IF(ISERROR($C$18),NA(),IF(AND(L21="",M21=""),"","Employment_Description_13")) -> Employment_Description_13 | D21: =IFERROR(INDEX('LU - Ad Hoc Baker Fix'!$D:$D,MATCH(M$18&$C21,'LU - Ad Hoc Baker Fix'!$A:$A,0)),$M21) -> Checked patient vitals such as temperature, blood pressure and blood sugar levels | E21: =IF(C21="Employment_1","September 2021 - Present",IF(C21="Employment_2","July 2020 - August 2021",IF(C21="Employment_3","April 2019 - June 2020",IF(C21="Employment_4","August 2017 - March 2019",IF(C21="Employment_5","October 2016 - July 2017",""))))) | F21: =IF(OR(AND(L18="Education",L21="2013-2017"),ISNUMBER(FIND("GED",M21))),"High School",IF(AND(L19="Education",L20="No Post-Secondary"),"Post Secondary",IF(AND(L19="Education",L20="Bachelor's Degree"),"Post Secondary",IF(AND(L19="Education",L20="Associate's Degree"),"Post Secondary","")))) | G21: =IF(L20="Certifications","Certification","") | H21: =IF(L20="Skills","Skill_1",IF(L19="Skills","Skill_2",IF(L18="Skills","Skill_3",IF(L17="Skills","Skill_4",IF(L16="Skills","Skill_5",IF(L15="Skills","Skill_6","")))))) | I21: =IF(L21="References available on request.","References","") | M21: Checked patient vitals such as temperature, blood pressure and blood sugar levels
A22: =B22&C22&F22&G22&H22&I22 -> Employment_Description_14 | B22: ="" | C22: =IF(ISERROR($C$18),NA(),IF(AND(L22="",M22=""),"","Employment_Description_14")) -> Employment_Description_14 | D22: =IFERROR(INDEX('LU - Ad Hoc Baker Fix'!$D:$D,MATCH(M$18&$C22,'LU - Ad Hoc Baker Fix'!$A:$A,0)),$M22) -> Cared for residents in assisted living facility and delivered high-quality support to meet needs | E22: =IF(C22="Employment_1","September 2021 - Present",IF(C22="Employment_2","July 2020 - August 2021",IF(C22="Employment_3","April 2019 - June 2020",IF(C22="Employment_4","August 2017 - March 2019",IF(C22="Employment_5","October 2016 - July 2017",""))))) | G22: =IF(L21="Certifications","Certification","") | M22: Cared for residents in assisted living facility and delivered high-quality support to meet needs
A23: =B23&C23&F23&G23&H23&I23 -> Employment_Description_15 | B23: ="" | C23: =IF(ISERROR($C$18),NA(),IF(AND(L23="",M23=""),"","Employment_Description_15")) -> Employment_Description_15 | D23: =IFERROR(INDEX('LU - Ad Hoc Baker Fix'!$D:$D,MATCH(M$18&$C23,'LU - Ad Hoc Baker Fix'!$A:$A,0)),$M23) -> Practiced proper perineal care to provide comfort and skin integrity | E23: =IF(C23="Employment_1","September 2021 - Present",IF(C23="Employment_2","July 2020 - August 2021",IF(C23="Employment_3","April 2019 - June 2020",IF(C23="Employment_4","August 2017 - March 2019",IF(C23="Employment_5","October 2016 - July 2017",""))))) | F23: =IF(OR(AND(L19="Education",L23="2013-2017"),ISNUMBER(FIND("GED",M23))),"High School",IF(AND(L20="Education",L21="No Post-Secondary"),"Post Secondary",IF(AND(L20="Education",L21="Bachelor's Degree"),"Post Secondary",IF(AND(L20="Education",L21="Associate's Degree"),"Post Secondary","")))) | G23: =IF(L22="Certifications","Certification","") | H23: =IF(L21="Skills","Skill_1",IF(L20="Skills","Skill_2",IF(L19="Skills","Skill_3",IF(L18="Skills","Skill_4",IF(L17="Skills","Skill_5",IF(L16="Skills","Skill_6","")))))) | I23: =IF(L23="References available on request.","References","") | M23: Practiced proper perineal care to provide comfort and skin integrity
A24: =B24&C24&F24&G24&H24&I24 | B24: ="" | C24: ="" | E24: =IF(C24="Employment_1","September 2021 - Present",IF(C24="Employment_2","July 2020 - August 2021",IF(C24="Employment_3","April 2019 - June 2020",IF(C24="Employment_4","August 2017 - March 2019",IF(C24="Employment_5","October 2016 - July 2017",""))))) | F24: =IF(OR(AND(L20="Education",L24="2013-2017"),ISNUMBER(FIND("GED",M24))),"High School",IF(AND(L21="Education",L23="No Post-Secondary"),"Post Secondary",IF(AND(L21="Education",L23="Bachelor's Degree"),"Post Secondary",IF(AND(L21="Education",L23="Associate's Degree"),"Post Secondary","")))) | G24: =IF(L23="Certifications","Certification","") | H24: =IF(L23="Skills","Skill_1",IF(L21="Skills","Skill_2",IF(L20="Skills","Skill_3",IF(L19="Skills","Skill_4",IF(L18="Skills","Skill_5",IF(L17="Skills","Skill_6","")))))) | I24: =IF(L24="References available on request.","References","")
A25: =B25&C25&F25&G25&H25&I25 -> Employment_3 | B25: ="" | C25: =IF(C$18="#N/A",NA(),IF(AND(L25="",M25=""),"",IF(LEFT(L25,1)="2","Employment_"&RIGHT(C18,1)+2,""))) -> Employment_3 | E25: =IF(C25="Employment_1","September 2021 - Present",IF(C25="Employment_2","July 2020 - August 2021",IF(C25="Employment_3","April 2019 - June 2020",IF(C25="Employment_4","August 2017 - March 2019",IF(C25="Employment_5","October 2016 - July 2017",""))))) -> April 2019 - June 2020 | F25: =IF(OR(AND(L21="Education",L25="2013-2017"),ISNUMBER(FIND("GED",M25))),"High School",IF(AND(L23="Education",L24="No Post-Secondary"),"Post Secondary",IF(AND(L23="Education",L24="Bachelor's Degree"),"Post Secondary",IF(AND(L23="Education",L24="Associate's Degree"),"Post Secondary","")))) | G25: =IF(L24="Certifications","Certification","") | H25: =IF(L24="Skills","Skill_1",IF(L23="Skills","Skill_2",IF(L21="Skills","Skill_3",IF(L20="Skills","Skill_4",IF(L19="Skills","Skill_5",IF(L18="Skills","Skill_6","")))))) | I25: =IF(L25="References available on request.","References","") | L25: 2020-2021 | M25: Delivery Driver | N25: Company B
A26: =B26&C26&F26&G26&H26&I26 -> Employment_Description_31 | B26: ="" | C26: =IF(C$18="#N/A",NA(),IF(C$25="","",IF(AND(L26="",M26=""),"","Employment_Description_"&LEFT(RIGHT(C19,2),1)+2&RIGHT(C19,1)))) -> Employment_Description_31 | D26: =IFERROR(INDEX('LU - Ad Hoc Baker Fix'!$D:$D,MATCH(M$25&$C26,'LU - Ad Hoc Baker Fix'!$A:$A,0)),$M26) -> Deliver and follow directions to customers house | E26: =IF(C26="Employment_1","September 2021 - Present",IF(C26="Employment_2","July 2020 - August 2021",IF(C26="Employment_3","April 2019 - June 2020",IF(C26="Employment_4","August 2017 - March 2019",IF(C26="Employment_5","October 2016 - July 2017",""))))) | F26: =IF(OR(AND(L23="Education",L26="2013-2017"),ISNUMBER(FIND("GED",M26))),"High School",IF(AND(L24="Education",L25="No Post-Secondary"),"Post Secondary",IF(AND(L24="Education",L25="Bachelor's Degree"),"Post Secondary",IF(AND(L24="Education",L25="Associate's Degree"),"Post Secondary","")))) | G26: =IF(L25="Certifications","Certification","") | H26: =IF(L25="Skills","Skill_1",IF(L24="Skills","Skill_2",IF(L23="Skills","Skill_3",IF(L21="Skills","Skill_4",IF(L20="Skills","Skill_5",IF(L19="Skills","Skill_6","")))))) | I26: =IF(L26="References available on request.","References","") | M26: Deliver and follow directions to customers house
A27: =B27&C27&F27&G27&H27&I27 -> Employment_Description_32 | B27: ="" | C27: =IF(C$18="#N/A",NA(),IF(C$25="","",IF(AND(L27="",M27=""),"","Employment_Description_"&LEFT(RIGHT(C20,2),1)+2&RIGHT(C20,1)))) -> Employment_Description_32 | D27: =IFERROR(INDEX('LU - Ad Hoc Baker Fix'!$D:$D,MATCH(M$25&$C27,'LU - Ad Hoc Baker Fix'!$A:$A,0)),$M27) -> Provide customer service at counter | E27: =IF(C27="Employment_1","September 2021 - Present",IF(C27="Employment_2","July 2020 - August 2021",IF(C27="Employment_3","April 2019 - June 2020",IF(C27="Employment_4","August 2017 - March 2019",IF(C27="Employment_5","October 2016 - July 2017",""))))) | F27: =IF(OR(AND(L24="Education",L27="2013-2017"),ISNUMBER(FIND("GED",M27))),"High School",IF(AND(L25="Education",L26="No Post-Secondary"),"Post Secondary",IF(AND(L25="Education",L26="Bachelor's Degree"),"Post Secondary",IF(AND(L25="Education",L26="Associate's Degree"),"Post Secondary","")))) | G27: =IF(L26="Certifications","Certification","") | H27: =IF(L26="Skills","Skill_1",IF(L25="Skills","Skill_2",IF(L24="Skills","Skill_3",IF(L23="Skills","Skill_4",IF(L21="Skills","Skill_5",IF(L20="Skills","Skill_6","")))))) | I27: =IF(L27="References available on request.","References","") | M27: Provide customer service at counter
A28: =B28&C28&F28&G28&H28&I28 -> Employment_Description_33 | B28: ="" | C28: =IF(C$18="#N/A",NA(),IF(C$25="","",IF(AND(L28="",M28=""),"","Employment_Description_"&LEFT(RIGHT(C21,2),1)+2&RIGHT(C21,1)))) -> Employment_Description_33 | D28: =IFERROR(INDEX('LU - Ad Hoc Baker Fix'!$D:$D,MATCH(M$25&$C28,'LU - Ad Hoc Baker Fix'!$A:$A,0)),$M28) -> Clean up for closing | E28: =IF(C28="Employment_1","September 2021 - Present",IF(C28="Employment_2","July 2020 - August 2021",IF(C28="Employment_3","April 2019 - June 2020",IF(C28="Employment_4","August 2017 - March 2019",IF(C28="Employment_5","October 2016 - July 2017",""))))) | F28: =IF(OR(AND(L25="Education",L28="2013-2017"),ISNUMBER(FIND("GED",M28))),"High School",IF(AND(L26="Education",L27="No Post-Secondary"),"Post Secondary",IF(AND(L26="Education",L27="Bachelor's Degree"),"Post Secondary",IF(AND(L26="Education",L27="Associate's Degree"),"Post Secondary","")))) | G28: =IF(L27="Certifications","Certification","") | H28: =IF(L27="Skills","Skill_1",IF(L26="Skills","Skill_2",IF(L25="Skills","Skill_3",IF(L24="Skills","Skill_4",IF(L23="Skills","Skill_5",IF(L21="Skills","Skill_6","")))))) | I28: =IF(L28="References available on request.","References","") | M28: Clean up for closing
A29: =B29&C29&F29&G29&H29&I29 -> Employment_Description_34 | B29: ="" | C29: =IF(C$18="#N/A",NA(),IF(C$25="","",IF(AND(L29="",M29=""),"","Employment_Description_"&LEFT(RIGHT(C22,2),1)+2&RIGHT(C22,1)))) -> Employment_Description_34 | D29: =IFERROR(INDEX('LU - Ad Hoc Baker Fix'!$D:$D,MATCH(M$25&$C29,'LU - Ad Hoc Baker Fix'!$A:$A,0)),$M29) -> n/a | E29: =IF(C29="Employment_1","September 2021 - Present",IF(C29="Employment_2","July 2020 - August 2021",IF(C29="Employment_3","April 2019 - June 2020",IF(C29="Employment_4","August 2017 - March 2019",IF(C29="Employment_5","October 2016 - July 2017",""))))) | G29: =IF(L28="Certifications","Certification","") | M29: n/a
A30: =B30&C30&F30&G30&H30&I30 -> Employment_Description_35 | B30: ="" | C30: =IF(C$18="#N/A",NA(),IF(C$25="","",IF(AND(L30="",M30=""),"","Employment_Description_"&LEFT(RIGHT(C23,2),1)+2&RIGHT(C23,1)))) -> Employment_Description_35 | D30: =IFERROR(INDEX('LU - Ad Hoc Baker Fix'!$D:$D,MATCH(M$25&$C30,'LU - Ad Hoc Baker Fix'!$A:$A,0)),$M30) -> n/a | E30: =IF(C30="Employment_1","September 2021 - Present",IF(C30="Employment_2","July 2020 - August 2021",IF(C30="Employment_3","April 2019 - June 2020",IF(C30="Employment_4","August 2017 - March 2019",IF(C30="Employment_5","October 2016 - July 2017",""))))) | F30: =IF(OR(AND(L26="Education",L30="2013-2017"),ISNUMBER(FIND("GED",M30))),"High School",IF(AND(L27="Education",L28="No Post-Secondary"),"Post Secondary",IF(AND(L27="Education",L28="Bachelor's Degree"),"Post Secondary",IF(AND(L27="Education",L28="Associate's Degree"),"Post Secondary","")))) | G30: =IF(L29="Certifications","Certification","") | H30: =IF(L28="Skills","Skill_1",IF(L27="Skills","Skill_2",IF(L26="Skills","Skill_3",IF(L25="Skills","Skill_4",IF(L24="Skills","Skill_5",IF(L23="Skills","Skill_6","")))))) | I30: =IF(L30="References available on request.","References","") | M30: n/a
A31: =B31&C31&F31&G31&H31&I31 | B31: ="" | C31: ="" | E31: =IF(C31="Employment_1","September 2021 - Present",IF(C31="Employment_2","July 2020 - August 2021",IF(C31="Employment_3","April 2019 - June 2020",IF(C31="Employment_4","August 2017 - March 2019",IF(C31="Employment_5","October 2016 - July 2017",""))))) | F31: =IF(OR(AND(L27="Education",L31="2013-2017"),ISNUMBER(FIND("GED",M31))),"High School",IF(AND(L28="Education",L30="No Post-Secondary"),"Post Secondary",IF(AND(L28="Education",L30="Bachelor's Degree"),"Post Secondary",IF(AND(L28="Education",L30="Associate's Degree"),"Post Secondary","")))) | G31: =IF(L30="Certifications","Certification","") | H31: =IF(L30="Skills","Skill_1",IF(L28="Skills","Skill_2",IF(L27="Skills","Skill_3",IF(L26="Skills","Skill_4",IF(L25="Skills","Skill_5",IF(L24="Skills","Skill_6","")))))) | I31: =IF(L31="References available on request.","References","")
A32: =B32&C32&F32&G32&H32&I32 -> Employment_4 | B32: ="" | C32: =IF(C$18="#N/A",NA(),IF(AND(L32="",M32=""),"",IF(LEFT(L32,1)="2","Employment_"&RIGHT(C25,1)+1,""))) -> Employment_4 | E32: =IF(C32="Employment_1","September 2021 - Present",IF(C32="Employment_2","July 2020 - August 2021",IF(C32="Employment_3","April 2019 - June 2020",IF(C32="Employment_4","August 2017 - March 2019",IF(C32="Employment_5","October 2016 - July 2017",""))))) -> August 2017 - March 2019 | F32: =IF(OR(AND(L28="Education",L32="2013-2017"),ISNUMBER(FIND("GED",M32))),"High School",IF(AND(L30="Education",L31="No Post-Secondary"),"Post Secondary",IF(AND(L30="Education",L31="Bachelor's Degree"),"Post Secondary",IF(AND(L30="Education",L31="Associate's Degree"),"Post Secondary","")))) | G32: =IF(L31="Certifications","Certification","") | H32: =IF(L31="Skills","Skill_1",IF(L30="Skills","Skill_2",IF(L28="Skills","Skill_3",IF(L27="Skills","Skill_4",IF(L26="Skills","Skill_5",IF(L25="Skills","Skill_6","")))))) | I32: =IF(L32="References available on request.","References","") | L32: 2019-2020 | M32: Administrative Assistant | N32: Company A
A33: =B33&C33&F33&G33&H33&I33 -> Employment_Description_41 | B33: ="" | C33: =IF(C$18="#N/A",NA(),IF(C$32="","",IF(AND(L33="",M33=""),"","Employment_Description_"&LEFT(RIGHT(C26,2),1)+1&RIGHT(C26,1)))) -> Employment_Description_41 | D33: =IFERROR(INDEX('LU - Ad Hoc Baker Fix'!$D:$D,MATCH(M$32&$C33,'LU - Ad Hoc Baker Fix'!$A:$A,0)),$M33) -> Serve as direct assistant to Office Manager, supporting all aspects of clerical and administrative needs | E33: =IF(C33="Employment_1","September 2021 - Present",IF(C33="Employment_2","July 2020 - August 2021",IF(C33="Employment_3","April 2019 - June 2020",IF(C33="Employment_4","August 2017 - March 2019",IF(C33="Employment_5","October 2016 - July 2017",""))))) | F33: =IF(OR(AND(L30="Education",L33="2013-2017"),ISNUMBER(FIND("GED",M33))),"High School",IF(AND(L31="Education",L32="No Post-Secondary"),"Post Secondary",IF(AND(L31="Education",L32="Bachelor's Degree"),"Post Secondary",IF(AND(L31="Education",L32="Associate's Degree"),"Post Secondary","")))) | G33: =IF(L32="Certifications","Certification","") | H33: =IF(L32="Skills","Skill_1",IF(L31="Skills","Skill_2",IF(L30="Skills","Skill_3",IF(L28="Skills","Skill_4",IF(L27="Skills","Skill_5",IF(L26="Skills","Skill_6","")))))) | I33: =IF(L33="References available on request.","References","") | M33: Serve as direct assistant to Office Manager, supporting all aspects of clerical and administrative needs
A34: =B34&C34&F34&G34&H34&I34 -> Employment_Description_42 | B34: ="" | C34: =IF(C$18="#N/A",NA(),IF(C$32="","",IF(AND(L34="",M34=""),"","Employment_Description_"&LEFT(RIGHT(C27,2),1)+1&RIGHT(C27,1)))) -> Employment_Description_42 | D34: =IFERROR(INDEX('LU - Ad Hoc Baker Fix'!$D:$D,MATCH(M$32&$C34,'LU - Ad Hoc Baker Fix'!$A:$A,0)),$M34) -> Alleviate executive overload by handling all patient interactions including walk-ins, email, phone, and fax coordination | E34: =IF(C34="Employment_1","September 2021 - Present",IF(C34="Employment_2","July 2020 - August 2021",IF(C34="Employment_3","April 2019 - June 2020",IF(C34="Employment_4","August 2017 - March 2019",IF(C34="Employment_5","October 2016 - July 2017",""))))) | F34: =IF(OR(AND(L31="Education",L34="2013-2017"),ISNUMBER(FIND("GED",M34))),"High School",IF(AND(L32="Education",L33="No Post-Secondary"),"Post Secondary",IF(AND(L32="Education",L33="Bachelor's Degree"),"Post Secondary",IF(AND(L32="Education",L33="Associate's Degree"),"Post Secondary","")))) | G34: =IF(L33="Certifications","Certification","") | H34: =IF(L33="Skills","Skill_1",IF(L32="Skills","Skill_2",IF(L31="Skills","Skill_3",IF(L30="Skills","Skill_4",IF(L28="Skills","Skill_5",IF(L27="Skills","Skill_6","")))))) | I34: =IF(L34="References available on request.","References","") | M34: Alleviate executive overload by handling all patient interactions including walk-ins, email, phone, and fax coordination
A35: =B35&C35&F35&G35&H35&I35 -> Employment_Description_43 | B35: ="" | C35: =IF(C$18="#N/A",NA(),IF(C$32="","",IF(AND(L35="",M35=""),"","Employment_Description_"&LEFT(RIGHT(C28,2),1)+1&RIGHT(C28,1)))) -> Employment_Description_43 | D35: =IFERROR(INDEX('LU - Ad Hoc Baker Fix'!$D:$D,MATCH(M$32&$C35,'LU - Ad Hoc Baker Fix'!$A:$A,0)),$M35) -> Screen phone calls, taking messages, assisting callers, and rerouting as needed | E35: =IF(C35="Employment_1","September 2021 - Present",IF(C35="Employment_2","July 2020 - August 2021",IF(C35="Employment_3","April 2019 - June 2020",IF(C35="Employment_4","August 2017 - March 2019",IF(C35="Employment_5","October 2016 - July 2017",""))))) | F35: =IF(OR(AND(L32="Education",L35="2013-2017"),ISNUMBER(FIND("GED",M35))),"High School",IF(AND(L33="Education",L34="No Post-Secondary"),"Post Secondary",IF(AND(L33="Education",L34="Bachelor's Degree"),"Post Secondary",IF(AND(L33="Education",L34="Associate's Degree"),"Post Secondary","")))) | G35: =IF(L34="Certifications","Certification","") | H35: =IF(L34="Skills","Skill_1",IF(L33="Skills","Skill_2",IF(L32="Skills","Skill_3",IF(L31="Skills","Skill_4",IF(L30="Skills","Skill_5",IF(L28="Skills","Skill_6","")))))) | I35: =IF(L35="References available on request.","References","") | M35: Screen phone calls, taking messages, assisting callers, and rerouting as needed
A36: =B36&C36&F36&G36&H36&I36 -> Employment_Description_44 | B36: ="" | C36: =IF(C$18="#N/A",NA(),IF(C$32="","",IF(AND(L36="",M36=""),"","Employment_Description_"&LEFT(RIGHT(C29,2),1)+1&RIGHT(C29,1)))) -> Employment_Description_44 | D36: =IFERROR(INDEX('LU - Ad Hoc Baker Fix'!$D:$D,MATCH(M$32&$C36,'LU - Ad Hoc Baker Fix'!$A:$A,0)),$M36) -> Act as the first step in Billing by collecting accurate demographic and insurance information from patients | E36: =IF(C36="Employment_1","September 2021 - Present",IF(C36="Employment_2","July 2020 - August 2021",IF(C36="Employment_3","April 2019 - June 2020",IF(C36="Employment_4","August 2017 - March 2019",IF(C36="Employment_5","October 2016 - July 2017",""))))) | G36: =IF(L35="Certifications","Certification","") | M36: Act as the first step in Billing by collecting accurate demographic and insurance information from patients
A37: =B37&C37&F37&G37&H37&I37 -> Employment_Description_45 | B37: ="" | C37: =IF(C$18="#N/A",NA(),IF(C$32="","",IF(AND(L37="",M37=""),"","Employment_Description_"&LEFT(RIGHT(C30,2),1)+1&RIGHT(C30,1)))) -> Employment_Description_45 | D37: =IFERROR(INDEX('LU - Ad Hoc Baker Fix'!$D:$D,MATCH(M$32&$C37,'LU - Ad Hoc Baker Fix'!$A:$A,0)),$M37) -> n/a | E37: =IF(C37="Employment_1","September 2021 - Present",IF(C37="Employment_2","July 2020 - August 2021",IF(C37="Employment_3","April 2019 - June 2020",IF(C37="Employment_4","August 2017 - March 2019",IF(C37="Employment_5","October 2016 - July 2017",""))))) | F37: =IF(OR(AND(L33="Education",L37="2013-2017"),ISNUMBER(FIND("GED",M37))),"High School",IF(AND(L34="Education",L35="No Post-Secondary"),"Post Secondary",IF(AND(L34="Education",L35="Bachelor's Degree"),"Post Secondary",IF(AND(L34="Education",L35="Associate's Degree"),"Post Secondary","")))) | G37: =IF(L36="Certifications","Certification","") | H37: =IF(L35="Skills","Skill_1",IF(L34="Skills","Skill_2",IF(L33="Skills","Skill_3",IF(L32="Skills","Skill_4",IF(L31="Skills","Skill_5",IF(L30="Skills","Skill_6","")))))) | I37: =IF(L37="References available on request.","References","") | M37: n/a
A38: =B38&C38&F38&G38&H38&I38 | B38: ="" | C38: ="" | E38: =IF(C38="Employment_1","September 2021 - Present",IF(C38="Employment_2","July 2020 - August 2021",IF(C38="Employment_3","April 2019 - June 2020",IF(C38="Employment_4","August 2017 - March 2019",IF(C38="Employment_5","October 2016 - July 2017",""))))) | F38: =IF(OR(AND(L34="Education",L38="2013-2017"),ISNUMBER(FIND("GED",M38))),"High School",IF(AND(L35="Education",L37="No Post-Secondary"),"Post Secondary",IF(AND(L35="Education",L37="Bachelor's Degree"),"Post Secondary",IF(AND(L35="Education",L37="Associate's Degree"),"Post Secondary","")))) | G38: =IF(L37="Certifications","Certification","") | H38: =IF(L37="Skills","Skill_1",IF(L35="Skills","Skill_2",IF(L34="Skills","Skill_3",IF(L33="Skills","Skill_4",IF(L32="Skills","Skill_5",IF(L31="Skills","Skill_6","")))))) | I38: =IF(L38="References available on request.","References","")
A39: =B39&C39&F39&G39&H39&I39 -> Employment_2 | B39: ="" | C39: =IF(C$18="#N/A",NA(),IF(AND(L39="",M39=""),"",IF(LEFT(L39,1)="2","Employment_"&RIGHT(C32,1)-2,""))) -> Employment_2 | E39: =IF(C39="Employment_1","September 2021 - Present",IF(C39="Employment_2","July 2020 - August 2021",IF(C39="Employment_3","April 2019 - June 2020",IF(C39="Employment_4","August 2017 - March 2019",IF(C39="Employment_5","October 2016 - July 2017",""))))) -> July 2020 - August 2021 | F39: =IF(OR(AND(L35="Education",L39="2013-2017"),ISNUMBER(FIND("GED",M39))),"High School",IF(AND(L37="Education",L38="No Post-Secondary"),"Post Secondary",IF(AND(L37="Education",L38="Bachelor's Degree"),"Post Secondary",IF(AND(L37="Education",L38="Associate's Degree"),"Post Secondary","")))) | G39: =IF(L38="Certifications","Certification","") | H39: =IF(L38="Skills","Skill_1",IF(L37="Skills","Skill_2",IF(L35="Skills","Skill_3",IF(L34="Skills","Skill_4",IF(L33="Skills","Skill_5",IF(L32="Skills","Skill_6","")))))) | I39: =IF(L39="References available on request.","References","") | L39: 2018-2019 | M39: Host | N39: Company A
A40: =B40&C40&F40&G40&H40&I40 -> Employment_Description_21 | B40: ="" | C40: =IF(C$18="#N/A",NA(),IF(C$39="","",IF(AND(L40="",M40=""),"","Employment_Description_"&LEFT(RIGHT(C33,2),1)-2&RIGHT(C33,1)))) -> Employment_Description_21 | D40: =IFERROR(INDEX('LU - Ad Hoc Baker Fix'!$D:$D,MATCH(M$39&$C40,'LU - Ad Hoc Baker Fix'!$A:$A,0)),$M40) -> Responsible for greeting and seating customers, including managing wait lists | E40: =IF(C40="Employment_1","September 2021 - Present",IF(C40="Employment_2","July 2020 - August 2021",IF(C40="Employment_3","April 2019 - June 2020",IF(C40="Employment_4","August 2017 - March 2019",IF(C40="Employment_5","October 2016 - July 2017",""))))) | F40: =IF(OR(AND(L37="Education",L40="2013-2017"),ISNUMBER(FIND("GED",M40))),"High School",IF(AND(L38="Education",L39="No Post-Secondary"),"Post Secondary",IF(AND(L38="Education",L39="Bachelor's Degree"),"Post Secondary",IF(AND(L38="Education",L39="Associate's Degree"),"Post Secondary","")))) | G40: =IF(L39="Certifications","Certification","") | H40: =IF(L39="Skills","Skill_1",IF(L38="Skills","Skill_2",IF(L37="Skills","Skill_3",IF(L35="Skills","Skill_4",IF(L34="Skills","Skill_5",IF(L33="Skills","Skill_6","")))))) | I40: =IF(L40="References available on request.","References","") | M40: Responsible for greeting and seating customers, including managing wait lists
...

Sheet COPY - Match 2
H1: Step Three: Copy Column H into Overleaf, starting at H3
H3: %-------------------------------------------------------------%
H4: % DOCUMENT CLASS
H5: %-------------------------------------------------------------%
H6: %
H7: % article class enables full customization of page
H8: \documentclass[a4paper,12pt]{article}
H9: % IF RESUME GOES BEYOND ONE PAGE, CHANGE TO 11PT OR 10PT ABOVE!!!
H10: %
H11: %-------------------------------------------------------------%
H12: % PACKAGES
H13: %-------------------------------------------------------------%
... H39: \Large
A40: Name | B40: =INDEX('PASTE - Match 2'!L:L,MATCH($A40,'PASTE - Match 2'!$A:$A,0)) -> Male Name 2 | C40: =INDEX('LU - Names'!$D:$D,MATCH('PASTE - Match 2'!$O$1&B40,'LU - Names'!$A:$A,0)) -> Adrian Nelson | H40: ="\hspace{-17 pt}\textbf{"&$C40&"} \\" -> \hspace{-17 pt}\textbf{Adrian Nelson} \\
H41: \large
A42: Pronouns | B42: =INDEX('PASTE - Match 2'!L:L,MATCH($A42,'PASTE - Match 2'!$A:$A,0)) -> no pronouns | H42: =IF(B42="no pronouns","%","{"&B42&"} \ $|$ \ %pronouns") -> %
A43: Location | B43: ='PASTE - Match 2'!$O$1 -> Denver, CO | H43: ="{"&B43&"} \ $|$ \ %location" -> {Denver, CO} \ $|$ \ %location
A44: Email | B44: =INDEX('LU - Emails'!B:B,MATCH(C40,'LU - Emails'!A:A,0)) -> adrian.m.nelson@outlook.com | H44: ="{"&B44&"} \ $|$ \ %email" -> {adrian.m.nelson@outlook.com} \ $|$ \ %email
A45: Phone | B45: =INDEX('PASTE - Match 2'!L:L,MATCH($A45,'PASTE - Match 2'!$A:$A,0)) -> Phone Number 2 | C45: =INDEX('LU - Phone Numbers'!D:D,MATCH(B43&B45,'LU - Phone Numbers'!A:A,0)) -> 1-720-738-0456 | H45: ="{("&LEFT(RIGHT(C45,12),3)&")-"&RIGHT(C45,8)&"} %phone" -> {(720)-738-0456} %phone
H46: %
H47: %-------------------------------------------------------------%
H48: % OBJECTIVE
H49: %-------------------------------------------------------------%
H50: =IF(C51=0,"%","\\[0.5cm]") -> %
A51: Summary | B51: =INDEX('PASTE - Match 2'!K:K,MATCH($A51,'PASTE - Match 2'!$A:$A,0)) -> 0 | C51: =INDEX('PASTE - Match 2'!L:L,MATCH($A51,'PASTE - Match 2'!$A:$A,0)) -> 0 | D51: =INDEX('PASTE - Match 2'!M:M,MATCH($A51,'PASTE - Match 2'!$A:$A,0)) -> 0 | H51: =IF(C51=0,"%",C51&" %summary") -> %
H52: %
H53: %-------------------------------------------------------------%
H54: % EXPERIENCE
H55: %-------------------------------------------------------------%
H56: \\[0.5 cm]
H57: \Large
H58: \textbf{Work Experience} \\
H59: \large
H60: =IF(ISERROR(B61),"%","\begin{tabularx}{\linewidth}{ @{}l r@{} }") -> \begin{tabularx}{\linewidth}{ @{}l r@{} }
A61: Employment_1 | B61: =INDEX('PASTE - Match 2'!E:E,MATCH($A61,'PASTE - Match 2'!$A:$A,0)) -> September 2021 - Present | C61: =INDEX('PASTE - Match 2'!M:M,MATCH($A61,'PASTE - Match 2'!$A:$A,0)) -> Certified Nursing Assistant | D61: =IF(C65="Take deliveries and make bank runs every once in a while","Company E",INDEX('PASTE - Match 2'!N:N,MATCH($A61,'PASTE - Match 2'!$A:$A,0))) -> Company D | E61: =IF(RIGHT(C61,1)=" ",LEFT(C61,LEN(C61)-1),C61) -> Certified Nursing Assistant | F61: =IF(AND(E61="Campus Security Officer",ISTEXT($E$152)),$E$152,INDEX(INDEX('LU - Company Names'!$A:$Z,,MATCH('PASTE - Match 2'!$O$1,'LU - Company Names'!$1:$1,0)),MATCH(E61&$D61,'LU - Company Names'!$A:$A,0))) -> Denver Skilled Nursing and Rehabilitation Center | H61: =IF(ISERROR(B61),"%",B61&" $~~~$ "&F61&", "&E61&" \\[3.75pt]") -> September 2021 - Present $~~~$ Denver Skilled Nursing and Rehabilitation Center, Certified Nursing Assistant \\[3.75pt]
H62: =IF(ISERROR(B61),"%","\multicolumn{2}{@{}X@{}}{") -> \multicolumn{2}{@{}X@{}}{
H63: =IF(ISERROR(B61),"%","\begin{minipage}[t]{\linewidth}") -> \begin{minipage}[t]{\linewidth}
H64: =IF(ISERROR(B61),"%"," \begin{itemize}[nosep,after=\strut, leftmargin=1em, itemsep=3pt]") -> \begin{itemize}[nosep,after=\strut, leftmargin=1em, itemsep=3pt] | L64: References available on request.
A65: Employment_Description_11 | B65: =INDEX('PASTE - Match 2'!L:L,MATCH($A65,'PASTE - Match 2'!$A:$A,0)) -> 0 | C65: =INDEX('PASTE - Match 2'!D:D,MATCH($A65,'PASTE - Match 2'!$A:$A,0)) -> Answered call lights and supported patient comfort and safety by adjusting bed rails and equipment | D65: =INDEX('PASTE - Match 2'!N:N,MATCH($A65,'PASTE - Match 2'!$A:$A,0)) -> 0 | H65: =IF(ISERROR(B61),"%"," \item[--] "&C65&" %description") -> \item[--] Answered call lights and supported patient comfort and safety by adjusting bed rails and equipment %description
A66: Employment_Description_12 | B66: =INDEX('PASTE - Match 2'!L:L,MATCH($A66,'PASTE - Match 2'!$A:$A,0)) -> 0 | C66: =INDEX('PASTE - Match 2'!D:D,MATCH($A66,'PASTE - Match 2'!$A:$A,0)) -> Promoted good oral and personal hygiene by aiding patients with shaving, bathing, and teeth brushing | D66: =INDEX('PASTE - Match 2'!N:N,MATCH($A66,'PASTE - Match 2'!$A:$A,0)) -> 0 | H66: =IF(ISERROR(B61),"%"," \item[--] "&C66&IF(OR(C67="n/a",C67="n/a ",C67="n/a ")," \nobreak\vspace{0.5em} %description"," %description")) -> \item[--] Promoted good oral and personal hygiene by aiding patients with shaving, bathing, and teeth brushing %description
...

Sheet LU - Company Names
A1: ID1 | B1: ID2 | C1: Position | D1: Company | E1: Seattle, WA | F1: Spokane, WA | G1: Salt Lake City, UT | H1: Provo, UT | I1: Denver, CO | J1: Colorado Springs, CO
A2: =C2&D2 -> ReceptionistCompany A | B2: =C2&" "&D2 -> Receptionist Company A | C2: Receptionist | D2: Company A | E2: H\&R Block | F2: H\&R Block | G2: H\&R Block | H2: H\&R Block | I2: H\&R Block | J2: H\&R Block
A3: =C3&D3 -> Front Desk ReceptionistCompany B | B3: =C3&" "&D3 -> Front Desk Receptionist Company B | C3: Front Desk Receptionist | D3: Company B | E3: LaVida Massage | F3: Elements Massage | G3: The Spa at Four Seasons | H3: Massage Envy | I3: Massage Envy | J3: Massage Envy
A4: =C4&D4 -> Medical ReceptionistCompany C | B4: =C4&" "&D4 -> Medical Receptionist Company C | C4: Medical Receptionist | D4: Company C | E4: Sea Mar Community Health Centers | F4: Excelsior Family Medicine | G4: ENT Center of Utah | H4: Mountainlands Family Health Center | I4: A Better Back Clinic | J4: Peak Vista Community Health Centers
A5: =C5&D5 -> ReceptionistCompany D | B5: =C5&" "&D5 -> Receptionist Company D | C5: Receptionist | D5: Company D | E5: Greenlake Primary Care | F5: Rockwood Pediatric Clinic | G5: Pure Dermatology | H5: Family Care Center | I5: The Thyroid Clinic | J5: Revere Health
A6: =C6&D6 -> ReceptionistCompany E | B6: =C6&" "&D6 -> Receptionist Company E | C6: Receptionist | D6: Company E | E6: Holiday Inn | F6: Holiday Inn | G6: Holiday Inn | H6: Holiday Inn | I6: Holiday Inn | J6: Holiday Inn
A7: =C7&D7 -> Front Desk ReceptionistCompany F | B7: =C7&" "&D7 -> Front Desk Receptionist Company F | C7: Front Desk Receptionist | D7: Company F | E7: Planet Fitness | F7: Planet Fitness | G7: Planet Fitness | H7: Planet Fitness | I7: Planet Fitness | J7: Planet Fitness
A8: =C8&D8 -> Medical ReceptionistCompany G | B8: =C8&" "&D8 -> Medical Receptionist Company G | C8: Medical Receptionist | D8: Company G | E8: MultiCare Health System | F8: Roth Medical Clinic | G8: Holladay Healthcare Center | H8: Premier Family Medical | I8: Arbor Family Medicine | J8: Matthews Vu Medical Group
A9: =C9&D9 -> Dental ReceptionistCompany H | B9: =C9&" "&D9 -> Dental Receptionist Company H | C9: Dental Receptionist | D9: Company H | E9: Etheridge Family Dentistry | F9: Maple Street Family Dentistry | G9: Comfort Dental | H9: Comfort Dental | I9: Monarch Dental \& Orthodontics | J9: The Springs Modern Dentistry
A10: =C10&D10 -> Dental ReceptionistCompany I | B10: =C10&" "&D10 -> Dental Receptionist Company I | C10: Dental Receptionist | D10: Company I | E10: Seattle Dental Co. | F10: NorthView Family Dental | G10: City Center Dental | H10: Cougar Dental | I10: The Denver Dentists | J10: SmileCOS Dentistry
A11: =C11&D11 -> Veterinary ReceptionistCompany J | B11: =C11&" "&D11 -> Veterinary Receptionist Company J | C11: Veterinary Receptionist | D11: Company J | E11: Broadway Veterinary Hospital | F11: Hunter Veterinary Clinic | G11: CityVet | H11: Bear Creek Veterinary Hospital | I11: Sugar House Veterinary Hospital | J11: Park Animal Hospital
A12: =C12&D12 -> ReceptionistCompany K | B12: =C12&" "&D12 -> Receptionist Company K | C12: Receptionist | D12: Company K | E12: Days Inn | F12: Days Inn | G12: Days Inn | H12: Days Inn | I12: Days Inn | J12: Days Inn
A13: =C13&D13 -> ReceptionistCompany L | B13: =C13&" "&D13 -> Receptionist Company L | C13: Receptionist | D13: Company L | E13: Cogir of Queen Anne | F13: Fairwinds Retirement Community | G13: Peaks at Millcreek | H13: Summerfield Retirement | I13: San Marino Retirement Community | J13: Winslow Court Retirement Community | L13: retirement!
A14: =C14&D14 | B14: =C14&" "&D14
A15: =C15&D15 -> ReceptionistCompany B | B15: =C15&" "&D15 -> Receptionist Company B | C15: Receptionist | D15: Company B | E15: LaVida Massage | F15: Elements Massage | G15: The Spa at Four Seasons | H15: Massage Envy | I15: Massage Envy | J15: Massage Envy | K15: Repeated above in case template files are wrong
A16: =C16&D16 -> ReceptionistCompany C | B16: =C16&" "&D16 -> Receptionist Company C | C16: Receptionist | D16: Company C | E16: Sea Mar Community Health Centers | F16: Excelsior Family Medicine | G16: A Better Back Clinic | H16: Peak Vista Community Health Centers | I16: ENT Center of Utah | J16: Mountainlands Family Health Center
A17: =C17&D17 -> ReceptionistCompany F | B17: =C17&" "&D17 -> Receptionist Company F | C17: Receptionist | D17: Company F | E17: Planet Fitness | F17: Planet Fitness | G17: Planet Fitness | H17: Planet Fitness | I17: Planet Fitness | J17: Planet Fitness
A18: =C18&D18 -> ReceptionistCompany G | B18: =C18&" "&D18 -> Receptionist Company G | C18: Receptionist | D18: Company G | E18: MultiCare Health System | F18: Roth Medical Clinic | G18: Arbor Family Medicine | H18: Matthews Vu Medical Group | I18: Holladay Healthcare Center | J18: Premier Family Medical
A19: =C19&D19 -> ReceptionistCompany H | B19: =C19&" "&D19 -> Receptionist Company H | C19: Receptionist | D19: Company H | E19: Etheridge Family Dentistry | F19: Maple Street Family Dentistry | G19: Comfort Dental | H19: Comfort Dental | I19: Monarch Dental \& Orthodontics | J19: Provo Dental
A20: =C20&D20 -> ReceptionistCompany I | B20: =C20&" "&D20 -> Receptionist Company I | C20: Receptionist | D20: Company I | E20: Seattle Dental Co. | F20: NorthView Family Dental | G20: City Center Dental | H20: Cougar Dental | I20: The Denver Dentists | J20: SmileCOS Dentistry
A21: =C21&D21 -> ReceptionistCompany J | B21: =C21&" "&D21 -> Receptionist Company J | C21: Receptionist | D21: Company J | E21: Broadway Veterinary Hospital | F21: Hunter Veterinary Clinic | G21: CityVet | H21: Bear Creek Veterinary Hospital | I21: Sugar House Veterinary Hospital | J21: Park Animal Hospital
A22: =C22&D22 | B22: =C22&" "&D22
A23: =C23&D23 -> Front Desk ReceptionistCompany A | B23: =C23&" "&D23 -> Front Desk Receptionist Company A | C23: Front Desk Receptionist | D23: Company A | E23: H\&R Block | F23: H\&R Block | G23: H\&R Block | H23: H\&R Block | I23: H\&R Block | J23: H\&R Block | K23: Repeated above in case template files are wrong
A24: =C24&D24 -> Front Desk ReceptionistCompany D | B24: =C24&" "&D24 -> Front Desk Receptionist Company D | C24: Front Desk Receptionist | D24: Company D | E24: Greenlake Primary Care | F24: Rockwood Pediatric Clinic | G24: Pure Dermatology | H24: Family Care Center | I24: The Thyroid Clinic | J24: Revere Health
A25: =C25&D25 -> Front Desk ReceptionistCompany E | B25: =C25&" "&D25 -> Front Desk Receptionist Company E | C25: Front Desk Receptionist | D25: Company E | E25: Holiday Inn | F25: Holiday Inn | G25: Holiday Inn | H25: Holiday Inn | I25: Holiday Inn | J25: Holiday Inn
A26: =C26&D26 -> Front Desk ReceptionistCompany K | B26: =C26&" "&D26 -> Front Desk Receptionist Company K | C26: Front Desk Receptionist | D26: Company K | E26: Days Inn | F26: Days Inn | G26: Days Inn | H26: Days Inn | I26: Days Inn | J26: Days Inn
A27: =C27&D27 -> Front Desk ReceptionistCompany L | B27: =C27&" "&D27 -> Front Desk Receptionist Company L | C27: Front Desk Receptionist | D27: Company L | E27: Cogir of Queen Anne | F27: Fairwinds Retirement Community | G27: Peaks at Millcreek | H27: Summerfield Retirement | I27: San Marino Retirement Community | J27: Winslow Court Retirement Community
A28: =C28&D28 | B28: =C28&" "&D28
A29: =C29&D29 -> CashierCompany A | B29: =C29&" "&D29 -> Cashier Company A | C29: Cashier | D29: Company A | E29: Home Depot | F29: Home Depot | G29: Home Depot | H29: Home Depot | I29: Home Depot | J29: Home Depot
A30: =C30&D30 -> CashierCompany B | B30: =C30&" "&D30 -> Cashier Company B | C30: Cashier | D30: Company B | E30: Walmart | F30: Walmart | G30: Walmart | H30: Walmart | I30: Walmart | J30: Walmart
A31: =C31&D31 -> CashierCompany C | B31: =C31&" "&D31 -> Cashier Company C | C31: Cashier | D31: Company C | E31: Safeway | F31: Safeway | G31: Safeway | H31: Safeway | I31: Macey's | J31: Macey's
A32: =C32&D32 -> CashierCompany D | B32: =C32&" "&D32 -> Cashier Company D | C32: Cashier | D32: Company D | E32: Target | F32: Target | G32: Target | H32: Target | I32: Target | J32: Target
A33: =C33&D33 -> CashierCompany E | B33: =C33&" "&D33 -> Cashier Company E | C33: Cashier | D33: Company E | E33: Dollar Tree | F33: Dollar Tree | G33: Dollar Tree | H33: Dollar Tree | I33: Dollar Tree | J33: Dollar Tree
A34: =C34&D34 -> CashierCompany F | B34: =C34&" "&D34 -> Cashier Company F | C34: Cashier | D34: Company F | E34: QFC | F34: Rosauers | G34: Smith's | H34: Smith's | I34: King Soopers | J34: King Soopers
A35: =C35&D35 -> CashierCompany G | B35: =C35&" "&D35 -> Cashier Company G | C35: Cashier | D35: Company G | E35: McDonald's | F35: McDonald's | G35: McDonald's | H35: McDonald's | I35: McDonald's | J35: McDonald's
A36: =C36&D36 -> CashierCompany H | B36: =C36&" "&D36 -> Cashier Company H | C36: Cashier | D36: Company H | E36: Wendy's | F36: Wendy's | G36: Wendy's | H36: Wendy's | I36: Wendy's | J36: Wendy's
A37: =C37&D37 -> CashierCompany I | B37: =C37&" "&D37 -> Cashier Company I | C37: Cashier | D37: Company I | E37: Taco Bell | F37: Taco Bell | G37: Taco Bell | H37: Taco Bell | I37: Taco Bell | J37: Taco Bell
A38: =C38&D38 -> CashierCompany J | B38: =C38&" "&D38 -> Cashier Company J | C38: Cashier | D38: Company J | E38: 7-Eleven | F38: 7-Eleven | G38: 7-Eleven | H38: 7-Eleven | I38: 7-Eleven | J38: 7-Eleven
A39: =C39&D39 | B39: =C39&" "&D39
A40: =C40&D40 -> HousekeeperCompany A | B40: =C40&" "&D40 -> Housekeeper Company A | C40: Housekeeper | D40: Company A | E40: Marriott | F40: Marriott | G40: Marriott | H40: Marriott | I40: Marriott | J40: Marriott
...

Sheet LU - Position Name Conversion

Sheet LU - Certifications
A1: Certification | B1: Seattle, WA | C1: Spokane, WA | D1: Salt Lake City, UT | E1: Provo, UT | F1: Denver, CO | G1: Colorado Springs, CO | K1: only include occupation specific if needed (cook)
A2: Server Cert 1 | B2: Food Handling, MAST | C2: Food Handling, MAST | D2: Food Handling, DABC Certified | E2: Food Handling, DABC Certified | F2: Food Handling, TIPS | G2: Food Handling, TIPS
A3: Server Cert 2 | B3: MAST Permit, Food Handler Certification | C3: MAST Permit, Food Handler Certification | D3: On-Premises Alcohol Servers Permit, Food Handler Certification | E3: On-Premises Alcohol Servers Permit, Food Handler Certification | F3: Training for Intervention Procedures (TIPS), Food Handler Certification | G3: Training for Intervention Procedures (TIPS), Food Handler Certification

Sheet LU - Schools
A1: School | B1: Seattle, WA | C1: Spokane, WA | D1: Salt Lake City, UT | E1: Provo, UT | F1: Denver, CO | G1: Colorado Springs, CO | K1: only include occupation specific if needed (cook)
A2: College A | B2: Bellevue College | C2: Spokane Community College | D2: Salt Lake Community College | E2: Utah Valley University | F2: Community College Of Denver | G2: Pikes Peak State College
A3: College B | B3: Highline Community College | C3: Spokane Falls Community College | D3: Utah Valley University | E3: Snow College | F3: Front Range Community College | G3: Pikes Peak Community College
A4: University A | B4: University of Washington | C4: Eastern Washington University | D4: University of Utah | E4: Brigham Young University | F4: University of Colorado | G4: University of Colorado
A5: University B | B5: Washington State University | C5: Washington State University | D5: Brigham Young University | E5: Utah Valley University | F5: Metropolitan State University | G5: Colorado State University
A7: College C | B7: Le Cordon Bleu | C7: Spokane Community College | D7: Salt Lake Community College | E7: Utah Valley University | F7: Auguste Escoffier School of Culinary Arts | G7: Pikes Peak Community College
A8: College D | B8: Highline Community College | C8: Spokane Community College | D8: Salt Lake Community College | E8: Snow College | F8: Front Range Community College | G8: Pikes Peak Community College
A9: College E | B9: Highline Community College | C9: Spokane Community College | D9: Fortis College | E9: Fortis College | F9: Concorde Career College | G9: Pikes Peak State College
A10: College F | B10: Clover Park Technical College | C10: Spokane Community College | D10: Salt Lake Community College | E10: Utah Valley University | F10: Art Institute of Colorado | G10: Pikes Peak Community College
A14: High School A | B14: Ingraham High School | C14: Lewis \& Clark High School | D14: Skyline High School | E14: Timpview High School | F14: East High School | G14: Cheyenne Mountain High School
A15: High School B | B15: Nathan Hale High School | C15: Gonzaga Preparatory School | D15: Olympus High School | E15: Utah County Academy of Sciences | F15: DSST: Byers High School | G15: The Vanguard School Senior High
A16: High School C | B16: The Center School | C16: West Valley High School | D16: Bingham High School | E16: Provo High School | F16: Jefferson Academy High School | G16: Colorado Early Colleges Colorado Springs
A17: High School D | B17: Summit Public School: Sierra | C17: Spokane Valley High School | D17: Riverton High School | E17: Freedom Preparatory Academy | F17: Standley Lake High School | G17: Civa Charter Academy
... A19: High School F | B19: Foster High School | C19: Mica Peak High School | D19: Mana Academy Charter School | E19: Summit High School | F19: SOAR Academy | G19: Mitchell High School
A24: 2023 Best Public High Schools in the Colorado Springs Area - Niche

Sheet LU - Names
A1: ID | B1: Location | C1: Name_Input | D1: Name | E1: Email | F1: Indeed_Password | G1: Phone_Number
A2: =B2&C2 -> Seattle, WAFemale Name 1 | B2: Seattle, WA | C2: Female Name 1 | D2: Lindsay Campbell | E2: lindsay.a.campbell@outlook.com | F2: seeking a job | G2: 1-206-249-7320
A3: =B3&C3 -> Seattle, WAFemale Name 2 | B3: Seattle, WA | C3: Female Name 2 | D3: Jasmine Phillips | E3: jasmine.m.phillips@outlook.com | F3: looking for a job | G3: 1-206-809-1527
A4: =B4&C4 -> Seattle, WAMale Name 1 | B4: Seattle, WA | C4: Male Name 1 | D4: Marcus Thomas | E4: marcus.h.thomas@outlook.com | F4: 2023 job searcher | G4: 1-206-249-7320
A5: =B5&C5 -> Seattle, WAMale Name 2 | B5: Seattle, WA | C5: Male Name 2 | D5: Patrick Lewis | E5: patrick.d.lewis@outlook.com | F5: 23_syp_ras | G5: 1-206-809-1527
A6: =B6&C6 -> Spokane, WAFemale Name 1 | B6: Spokane, WA | C6: Female Name 1 | D6: Lindsay Campbell | E6: lindsay.a.campbell@outlook.com | F6: seeking a job | G6: 1-509-530-1976
A7: =B7&C7 -> Spokane, WAFemale Name 2 | B7: Spokane, WA | C7: Female Name 2 | D7: Jasmine Phillips | E7: jasmine.m.phillips@outlook.com | F7: looking for a job | G7: 1-509-288-4985
A8: =B8&C8 -> Spokane, WAMale Name 1 | B8: Spokane, WA | C8: Male Name 1 | D8: Marcus Thomas | E8: marcus.h.thomas@outlook.com | F8: 2023 job searcher | G8: 1-509-530-1976
A9: =B9&C9 -> Spokane, WAMale Name 2 | B9: Spokane, WA | C9: Male Name 2 | D9: Patrick Lewis | E9: patrick.d.lewis@outlook.com | F9: 23_syp_ras | G9: 1-509-288-4985
